<?xml version="1.0"?>
<robot
  name="argo_urdf_2">
  <link
    name="argo_base">
    <inertial>
      <origin
        xyz="-0.0287146112802265 2.27427526650059E-06 -0.0381581636610044"
        rpy="0 0 0" />
      <mass
        value="32.9230854907662" />
      <inertia
        ixx="0.50262556870673"
        ixy="2.64755785172109E-05"
        ixz="0.0516273031694707"
        iyy="1.30944756370371"
        iyz="6.39030326038844E-06"
        izz="1.57981157521551" />
    </inertial>
    <visual>
      <origin
        xyz="0 0 0"
        rpy="0 0 0" />
      <geometry>
        <mesh
          filename="package://argo_description/meshes/argo_base.STL" />
      </geometry>
      <material
        name="">
        <color
          rgba="0.792156862745098 0.819607843137255 0.933333333333333 1" />
      </material>
    </visual>
    <collision>
      <origin
        xyz="0 0 0"
        rpy="0 0 0" />
      <geometry>
        <mesh
          filename="package://argo_description/meshes/argo_base_col.STL" />
      </geometry>
    </collision>
  </link>
  <link
    name="FLW">
    <inertial>
      <origin
        xyz="0 0.0156139504736138 0"
        rpy="0 0 0" />
      <mass
        value="1.50789368049402" />
      <inertia
        ixx="0.00365307678558648"
        ixy="5.1636108652648E-20"
        ixz="2.64359085585098E-19"
        iyy="0.00597955732075583"
        iyz="-2.08311224067256E-21"
        izz="0.00365307678558648" />
    </inertial>
    <visual>
      <origin
        xyz="0 0 0"
        rpy="0 0 0" />
      <geometry>
        <mesh
          filename="package://argo_description/meshes/FLW.STL" />
      </geometry>
      <material
        name="">
        <color
          rgba="0.792156862745098 0.819607843137255 0.933333333333333 1" />
      </material>
    </visual>
    <collision>
      <origin
        xyz="0 0 0"
        rpy="0 0 0" />
      <geometry>
        <mesh
          filename="package://argo_description/meshes/FLW_col.STL" />
      </geometry>
    </collision>
  </link>
  <joint
    name="FLW_cont"
    type="continuous">
    <origin
      xyz="0.12882 0.19812 -0.12406"
      rpy="0 -1.1994E-16 0" />
    <parent
      link="argo_base" />
    <child
      link="FLW" />
    <axis
      xyz="0 1 0" />
  </joint>
  <link
    name="MLW">
    <inertial>
      <origin
        xyz="-1.11022302462516E-16 0.0156139504736138 -2.77555756156289E-17"
        rpy="0 0 0" />
      <mass
        value="1.50789368049402" />
      <inertia
        ixx="0.00365307678558648"
        ixy="-1.96783860550682E-20"
        ixz="-1.53748539592062E-19"
        iyy="0.00597955732075583"
        iyz="2.56422756461994E-20"
        izz="0.00365307678558648" />
    </inertial>
    <visual>
      <origin
        xyz="0 0 0"
        rpy="0 0 0" />
      <geometry>
        <mesh
          filename="package://argo_description/meshes/MLW.STL" />
      </geometry>
      <material
        name="">
        <color
          rgba="0.792156862745098 0.819607843137255 0.933333333333333 1" />
      </material>
    </visual>
    <collision>
      <origin
        xyz="0 0 0"
        rpy="0 0 0" />
      <geometry>
        <mesh
          filename="package://argo_description/meshes/MLW_col.STL" />
      </geometry>
    </collision>
  </link>
  <joint
    name="MLW_cont"
    type="continuous">
    <origin
      xyz="-0.079459 0.19812 -0.12406"
      rpy="0 -1.1994E-16 0" />
    <parent
      link="argo_base" />
    <child
      link="MLW" />
    <axis
      xyz="0 1 0" />
  </joint>
  <link
    name="RLW">
    <inertial>
      <origin
        xyz="1.11022302462516E-16 0.0156139504736138 -8.32667268468867E-17"
        rpy="0 0 0" />
      <mass
        value="1.50789368049402" />
      <inertia
        ixx="0.00365307678558648"
        ixy="-7.0757132097532E-20"
        ixz="2.68751351881889E-19"
        iyy="0.00597955732075583"
        iyz="1.10554828062947E-19"
        izz="0.00365307678558648" />
    </inertial>
    <visual>
      <origin
        xyz="0 0 0"
        rpy="0 0 0" />
      <geometry>
        <mesh
          filename="package://argo_description/meshes/RLW.STL" />
      </geometry>
      <material
        name="">
        <color
          rgba="0.792156862745098 0.819607843137255 0.933333333333333 1" />
      </material>
    </visual>
    <collision>
      <origin
        xyz="0 0 0"
        rpy="0 0 0" />
      <geometry>
        <mesh
          filename="package://argo_description/meshes/RLW_col.STL" />
      </geometry>
    </collision>
  </link>
  <joint
    name="RLW_cont"
    type="continuous">
    <origin
      xyz="-0.28774 0.19812 -0.12406"
      rpy="0 -1.1994E-16 0" />
    <parent
      link="argo_base" />
    <child
      link="RLW" />
    <axis
      xyz="0 1 0" />
  </joint>
  <link
    name="FRW">
    <inertial>
      <origin
        xyz="5.55111512312578E-17 -0.0156139504736139 0"
        rpy="0 0 0" />
      <mass
        value="1.50789368049402" />
      <inertia
        ixx="0.00365307678558648"
        ixy="4.05259849993083E-20"
        ixz="4.25308640713539E-19"
        iyy="0.00597955732075583"
        iyz="-4.92635009524994E-20"
        izz="0.00365307678558648" />
    </inertial>
    <visual>
      <origin
        xyz="0 0 0"
        rpy="0 0 0" />
      <geometry>
        <mesh
          filename="package://argo_description/meshes/FRW.STL" />
      </geometry>
      <material
        name="">
        <color
          rgba="0.792156862745098 0.819607843137255 0.933333333333333 1" />
      </material>
    </visual>
    <collision>
      <origin
        xyz="0 0 0"
        rpy="0 0 0" />
      <geometry>
        <mesh
          filename="package://argo_description/meshes/FRW_col.STL" />
      </geometry>
    </collision>
  </link>
  <joint
    name="FRW_cont"
    type="continuous">
    <origin
      xyz="0.128821215414625 -0.19812 -0.124058737135444"
      rpy="0 0 0" />
    <parent
      link="argo_base" />
    <child
      link="FRW" />
    <axis
      xyz="0 -1 0" />
  </joint>
  <link
    name="MRW">
    <inertial>
      <origin
        xyz="0 -0.0156139504736138 1.38777878078145E-16"
        rpy="0 0 0" />
      <mass
        value="1.50789368049402" />
      <inertia
        ixx="0.00365307678558648"
        ixy="1.31117846911124E-21"
        ixz="-5.15282286567131E-19"
        iyy="0.00597955732075583"
        iyz="-2.1351225407273E-20"
        izz="0.00365307678558648" />
    </inertial>
    <visual>
      <origin
        xyz="0 0 0"
        rpy="0 0 0" />
      <geometry>
        <mesh
          filename="package://argo_description/meshes/MRW.STL" />
      </geometry>
      <material
        name="">
        <color
          rgba="0.792156862745098 0.819607843137255 0.933333333333333 1" />
      </material>
    </visual>
    <collision>
      <origin
        xyz="0 0 0"
        rpy="0 0 0" />
      <geometry>
        <mesh
          filename="package://argo_description/meshes/MRW_col.STL" />
      </geometry>
    </collision>
  </link>
  <joint
    name="MRW_cont"
    type="continuous">
    <origin
      xyz="-0.079459 -0.19812 -0.12406"
      rpy="0 -1.1994E-16 0" />
    <parent
      link="argo_base" />
    <child
      link="MRW" />
    <axis
      xyz="0 -1 0" />
  </joint>
  <link
    name="RRW">
    <inertial>
      <origin
        xyz="-1.11022302462516E-16 -0.0156139504736139 0"
        rpy="0 0 0" />
      <mass
        value="1.50789368049402" />
      <inertia
        ixx="0.00365307678558648"
        ixy="1.06637185456317E-19"
        ixz="1.35525271560688E-20"
        iyy="0.00597955732075583"
        iyz="-1.42529762888991E-20"
        izz="0.00365307678558648" />
    </inertial>
    <visual>
      <origin
        xyz="0 0 0"
        rpy="0 0 0" />
      <geometry>
        <mesh
          filename="package://argo_description/meshes/RRW.STL" />
      </geometry>
      <material
        name="">
        <color
          rgba="0.792156862745098 0.819607843137255 0.933333333333333 1" />
      </material>
    </visual>
    <collision>
      <origin
        xyz="0 0 0"
        rpy="0 0 0" />
      <geometry>
        <mesh
          filename="package://argo_description/meshes/RRW_col.STL" />
      </geometry>
    </collision>
  </link>
  <joint
    name="RRW_cont"
    type="continuous">
    <origin
      xyz="-0.28774 -0.19812 -0.12406"
      rpy="0 -0.010714 0" />
    <parent
      link="argo_base" />
    <child
      link="RRW" />
    <axis
      xyz="0 -1 0" />
  </joint>
</robot>
