<?xml version="1.0" ?>
<!-- =================================================================================== -->
<!-- |    This document was autogenerated by xacro from /home/bismaya/catkin_ws/src/argo_description/urdf/argo_urdf_2.xacro | -->
<!-- |    EDITING THIS FILE BY HAND IS NOT RECOMMENDED                                 | -->
<!-- =================================================================================== -->
<robot name="argo_urdf_2" xmlns:xacro="http://ros.org/wiki/xacro">
  <!-- Size of square 'camera' box -->
  <!-- Import all Gazebo-customization elements, including Gazebo colors -->
  <!-- ros_control plugin -->
  <gazebo>
    <plugin filename="libgazebo_ros_control.so" name="gazebo_ros_control">
      <robotNamespace>/</robotNamespace>
      <robotSimType>gazebo_ros_control/DefaultRobotHWSim</robotSimType>
    </plugin>
  </gazebo>
  <!-- Link1 -->
  <gazebo reference="base_link">
    <material>Gazebo/Orange</material>
  </gazebo>
  <!-- Link2 -->
  <gazebo reference="FLW">
    <material>Gazebo/Grey</material>
    <mu1 value="1.0"/>
    <mu2 value="1.0"/>
    <kp value="10000000.0"/>
    <kd value="1.0"/>
    <fdir1 value="1 0 0"/>
  </gazebo>
  <!-- Link2 -->
  <gazebo reference="FRW">
    <material>Gazebo/Grey</material>
    <mu1 value="1.0"/>
    <mu2 value="1.0"/>
    <kp value="10000000.0"/>
    <kd value="1.0"/>
    <fdir1 value="1 0 0"/>
  </gazebo>
  <!-- Link2 -->
  <gazebo reference="MLW">
    <material>Gazebo/Grey</material>
    <mu1 value="1.0"/>
    <mu2 value="1.0"/>
    <kp value="10000000.0"/>
    <kd value="1.0"/>
    <fdir1 value="1 0 0"/>
  </gazebo>
  <!-- Link2 -->
  <gazebo reference="MRW">
    <material>Gazebo/Grey</material>
    <mu1 value="1.0"/>
    <mu2 value="1.0"/>
    <kp value="10000000.0"/>
    <kd value="1.0"/>
    <fdir1 value="1 0 0"/>
  </gazebo>
  <!-- Link2 -->
  <gazebo reference="RLW">
    <material>Gazebo/Grey</material>
    <mu1 value="1.0"/>
    <mu2 value="1.0"/>
    <kp value="10000000.0"/>
    <kd value="1.0"/>
    <fdir1 value="1 0 0"/>
  </gazebo>
  <!-- Link2 -->
  <gazebo reference="RRW">
    <material>Gazebo/Grey</material>
    <mu1 value="1.0"/>
    <mu2 value="1.0"/>
    <kp value="10000000.0"/>
    <kd value="1.0"/>
    <fdir1 value="1 0 0"/>
  </gazebo>
  <!-- camera_link -->
  <gazebo reference="camera_link">
    <mu1>0.2</mu1>
    <mu2>0.2</mu2>
    <material>Gazebo/Red</material>
  </gazebo>
  <gazebo>
    <plugin filename="libhector_gazebo_ros_imu.so" name="imu_controller">
      <robotNamespace>/</robotNamespace>
      <updateRate>50.0</updateRate>
      <bodyName>base_link</bodyName>
      <topicName>/imu/data</topicName>
      <accelDrift>0.005 0.005 0.005</accelDrift>
      <accelGaussianNoise>0.005 0.005 0.005</accelGaussianNoise>
      <rateDrift>0.005 0.005 0.005 </rateDrift>
      <rateGaussianNoise>0.005 0.005 0.005 </rateGaussianNoise>
      <headingDrift>0.005</headingDrift>
      <headingGaussianNoise>0.005</headingGaussianNoise>
    </plugin>
  </gazebo>
  <gazebo>
    <plugin filename="libhector_gazebo_ros_gps.so" name="gps_controller">
      <updateRate>40</updateRate>
      <robotNamespace>/</robotNamespace>
      <bodyName>base_link</bodyName>
      <frameId>base_link</frameId>
      <topicName>navsat/fix</topicName>
      <velocityTopicName>navsat/vel</velocityTopicName>
      <referenceLatitude>49.9</referenceLatitude>
      <referenceLongitude>8.9</referenceLongitude>
      <referenceHeading>0</referenceHeading>
      <referenceAltitude>0</referenceAltitude>
      <drift>0.0001 0.0001 0.0001</drift>
    </plugin>
  </gazebo>
  <!--Skis Steer -->
  <gazebo>
    <plugin filename="libgazebo_ros_skid_steer_drive.so" name="skid_steer_drive_controller">
      <updateRate>100.0</updateRate>
      <robotNamespace>/</robotNamespace>
      <leftFrontJoint>FLW_cont</leftFrontJoint>
      <rightFrontJoint>FRW_cont</rightFrontJoint>
      <leftRearJoint>RLW_cont</leftRearJoint>
      <rightRearJoint>RRW_cont</rightRearJoint>
      <wheelSeparation>0.456</wheelSeparation>
      <wheelDiameter>0.35</wheelDiameter>
      <robotBaseFrame>base_link</robotBaseFrame>
      <torque>20</torque>
      <commandTopic>cmd_vel</commandTopic>
      <odometryTopic>odom</odometryTopic>
      <broadcastTF>false</broadcastTF>
    </plugin>
  </gazebo>
  <!-- Import Rviz colors -->
  <material name="black">
    <color rgba="0.0 0.0 0.0 1.0"/>
  </material>
  <material name="blue">
    <color rgba="0.0 0.0 0.8 1.0"/>
  </material>
  <material name="green">
    <color rgba="0.0 0.8 0.0 1.0"/>
  </material>
  <material name="grey">
    <color rgba="0.2 0.2 0.2 1.0"/>
  </material>
  <material name="orange">
    <color rgba="1.0 0.423529411765 0.0392156862745 1.0"/>
  </material>
  <material name="brown">
    <color rgba="0.870588235294 0.811764705882 0.764705882353 1.0"/>
  </material>
  <material name="red">
    <color rgba="0.8 0.0 0.0 1.0"/>
  </material>
  <material name="white">
    <color rgba="1.0 1.0 1.0 1.0"/>
  </material>
  <!--<link name="base_link"/>-->
  <link name="base_link">
    <inertial>
      <origin rpy="0 0 0" xyz="-0.0287146112802265 2.27427526650059E-06 -0.0381581636610044"/>
      <mass value="32.9230854907662"/>
      <inertia ixx="0.50262556870673" ixy="2.64755785172109E-05" ixz="0.0516273031694707" iyy="1.30944756370371" iyz="6.39030326038844E-06" izz="1.57981157521551"/>
    </inertial>
    <visual>
      <origin rpy="0 0 0" xyz="0 0 0"/>
      <geometry>
        <mesh filename="package://argo_description/meshes/argo_base.STL"/>
      </geometry>
      <material name="Yellow1">
        <color rgba="1.0 0.423529411765 0.0392156862745 1.0"/>
      </material>
    </visual>
    <collision>
      <origin rpy="0 0 0" xyz="0 0 0"/>
      <geometry>
        <mesh filename="package://argo_description/meshes/argo_base_col.STL"/>
      </geometry>
    </collision>
  </link>
  <!-- <joint name="base_link_joint" type="fixed">
      <origin xyz="0 0 0" rpy="0 0 0" />
      <parent link="base_link" />
      <child link="base_link" />
    </joint>-->
  <link name="FLW">
    <inertial>
      <origin rpy="0 0 0" xyz="0 0.0156139504736138 0"/>
      <mass value="1.50789368049402"/>
      <inertia ixx="0.00365307678558648" ixy="5.1636108652648E-20" ixz="2.64359085585098E-19" iyy="0.00597955732075583" iyz="-2.08311224067256E-21" izz="0.00365307678558648"/>
    </inertial>
    <visual>
      <origin rpy="0 0 0" xyz="0 0 0"/>
      <geometry>
        <mesh filename="package://argo_description/meshes/FLW.STL"/>
      </geometry>
      <material name="Grey">
        <color rgba="0.2 0.2 0.2 1.0"/>
      </material>
    </visual>
    <collision>
      <origin rpy="0 0 0" xyz="0 0 0"/>
      <geometry>
        <!--mesh
          filename="package://argo_description/meshes/FLW_col.STL" /-->
        <cylinder length="0.0762" radius="0.085"/>
      </geometry>
    </collision>
  </link>
  <joint name="FLW_cont" type="continuous">
    <origin rpy="0 -1.1994E-16 0" xyz="0.12882 0.19812 -0.12406"/>
    <parent link="base_link"/>
    <child link="FLW"/>
    <axis xyz="0 1 0"/>
  </joint>
  <link name="MLW">
    <inertial>
      <origin rpy="0 0 0" xyz="-1.11022302462516E-16 0.0156139504736138 -2.77555756156289E-17"/>
      <mass value="1.50789368049402"/>
      <inertia ixx="0.00365307678558648" ixy="-1.96783860550682E-20" ixz="-1.53748539592062E-19" iyy="0.00597955732075583" iyz="2.56422756461994E-20" izz="0.00365307678558648"/>
    </inertial>
    <visual>
      <origin rpy="0 0 0" xyz="0 0 0"/>
      <geometry>
        <mesh filename="package://argo_description/meshes/MLW.STL"/>
      </geometry>
      <material name="Grey">
        <color rgba="0.2 0.2 0.2 1.0"/>
      </material>
    </visual>
    <collision>
      <origin rpy="0 0 0" xyz="0 0 0"/>
      <geometry>
        <!--mesh
          filename="package://argo_description/meshes/MLW_col.STL" /-->
        <cylinder length="0.0762" radius="0.085"/>
      </geometry>
    </collision>
  </link>
  <joint name="MLW_cont" type="continuous">
    <origin rpy="0 -1.1994E-16 0" xyz="-0.079459 0.19812 -0.12406"/>
    <parent link="base_link"/>
    <child link="MLW"/>
    <axis xyz="0 1 0"/>
  </joint>
  <link name="RLW">
    <inertial>
      <origin rpy="0 0 0" xyz="1.11022302462516E-16 0.0156139504736138 -8.32667268468867E-17"/>
      <mass value="1.50789368049402"/>
      <inertia ixx="0.00365307678558648" ixy="-7.0757132097532E-20" ixz="2.68751351881889E-19" iyy="0.00597955732075583" iyz="1.10554828062947E-19" izz="0.00365307678558648"/>
    </inertial>
    <visual>
      <origin rpy="0 0 0" xyz="0 0 0"/>
      <geometry>
        <mesh filename="package://argo_description/meshes/RLW.STL"/>
      </geometry>
      <material name="Grey">
        <color rgba="0.2 0.2 0.2 1.0"/>
      </material>
    </visual>
    <collision>
      <origin rpy="0 0 0" xyz="0 0 0"/>
      <geometry>
        <!--mesh
          filename="package://argo_description/meshes/RLW_col.STL" /-->
        <cylinder length="0.0762" radius="0.085"/>
      </geometry>
    </collision>
  </link>
  <joint name="RLW_cont" type="continuous">
    <origin rpy="0 -1.1994E-16 0" xyz="-0.28774 0.19812 -0.12406"/>
    <parent link="base_link"/>
    <child link="RLW"/>
    <axis xyz="0 1 0"/>
  </joint>
  <link name="FRW">
    <inertial>
      <origin rpy="0 0 0" xyz="5.55111512312578E-17 -0.0156139504736139 0"/>
      <mass value="1.50789368049402"/>
      <inertia ixx="0.00365307678558648" ixy="4.05259849993083E-20" ixz="4.25308640713539E-19" iyy="0.00597955732075583" iyz="-4.92635009524994E-20" izz="0.00365307678558648"/>
    </inertial>
    <visual>
      <origin rpy="0 0 0" xyz="0 0 0"/>
      <geometry>
        <mesh filename="package://argo_description/meshes/FRW.STL"/>
      </geometry>
      <material name="Grey">
        <color rgba="0.2 0.2 0.2 1.0"/>
      </material>
    </visual>
    <collision>
      <origin rpy="0 0 0" xyz="0 0 0"/>
      <geometry>
        <!--mesh
          filename="package://argo_description/meshes/FRW_col.STL" /-->
        <cylinder length="0.0762" radius="0.085"/>
      </geometry>
    </collision>
  </link>
  <joint name="FRW_cont" type="continuous">
    <origin rpy="0 0 0" xyz="0.128821215414625 -0.19812 -0.124058737135444"/>
    <parent link="base_link"/>
    <child link="FRW"/>
    <axis xyz="0 1 0"/>
  </joint>
  <link name="MRW">
    <inertial>
      <origin rpy="0 0 0" xyz="0 -0.0156139504736138 1.38777878078145E-16"/>
      <mass value="1.50789368049402"/>
      <inertia ixx="0.00365307678558648" ixy="1.31117846911124E-21" ixz="-5.15282286567131E-19" iyy="0.00597955732075583" iyz="-2.1351225407273E-20" izz="0.00365307678558648"/>
    </inertial>
    <visual>
      <origin rpy="0 0 0" xyz="0 0 0"/>
      <geometry>
        <mesh filename="package://argo_description/meshes/MRW.STL"/>
      </geometry>
      <material name="Grey">
        <color rgba="0.2 0.2 0.2 1.0"/>
      </material>
    </visual>
    <collision>
      <origin rpy="0 0 0" xyz="0 0 0"/>
      <geometry>
        <!--mesh
          filename="package://argo_description/meshes/MRW_col.STL" /-->
        <cylinder length="0.0762" radius="0.085"/>
      </geometry>
    </collision>
  </link>
  <joint name="MRW_cont" type="continuous">
    <origin rpy="0 -1.1994E-16 0" xyz="-0.079459 -0.19812 -0.12406"/>
    <parent link="base_link"/>
    <child link="MRW"/>
    <axis xyz="0 1 0"/>
  </joint>
  <link name="RRW">
    <inertial>
      <origin rpy="0 0 0" xyz="-1.11022302462516E-16 -0.0156139504736139 0"/>
      <mass value="1.50789368049402"/>
      <inertia ixx="0.00365307678558648" ixy="1.06637185456317E-19" ixz="1.35525271560688E-20" iyy="0.00597955732075583" iyz="-1.42529762888991E-20" izz="0.00365307678558648"/>
    </inertial>
    <visual>
      <origin rpy="0 0 0" xyz="0 0 0"/>
      <geometry>
        <mesh filename="package://argo_description/meshes/RRW.STL"/>
      </geometry>
      <material name="Grey">
        <color rgba="0.2 0.2 0.2 1.0"/>
      </material>
    </visual>
    <collision>
      <origin rpy="0 0 0" xyz="0 0 0"/>
      <geometry>
        <!--mesh
          filename="package://argo_description/meshes/RRW_col.STL" /-->
        <cylinder length="0.0762" radius="0.085"/>
      </geometry>
    </collision>
  </link>
  <joint name="RRW_cont" type="continuous">
    <origin rpy="0 -0.010714 0" xyz="-0.28774 -0.19812 -0.12406"/>
    <parent link="base_link"/>
    <child link="RRW"/>
    <axis xyz="0 1 0"/>
  </joint>
  <transmission name="FL_wheel_trans" type="SimpleTransmission">
    <type>transmission_interface/SimpleTransmission</type>
    <actuator name="FL_wheel_motor">
      <mechanicalReduction>1</mechanicalReduction>
    </actuator>
    <joint name="FLW_cont">
      <hardwareInterface>VelocityJointInterface</hardwareInterface>
    </joint>
  </transmission>
  <transmission name="ML_wheel_trans" type="SimpleTransmission">
    <type>transmission_interface/SimpleTransmission</type>
    <actuator name="ML_wheel_motor">
      <mechanicalReduction>1</mechanicalReduction>
    </actuator>
    <joint name="MLW_cont">
      <hardwareInterface>VelocityJointInterface</hardwareInterface>
    </joint>
  </transmission>
  <transmission name="RL_wheel_trans" type="SimpleTransmission">
    <type>transmission_interface/SimpleTransmission</type>
    <actuator name="RL_wheel_motor">
      <mechanicalReduction>1</mechanicalReduction>
    </actuator>
    <joint name="RLW_cont">
      <hardwareInterface>VelocityJointInterface</hardwareInterface>
    </joint>
  </transmission>
  <transmission name="FR_wheel_trans" type="SimpleTransmission">
    <type>transmission_interface/SimpleTransmission</type>
    <actuator name="FR_wheel_motor">
      <mechanicalReduction>1</mechanicalReduction>
    </actuator>
    <joint name="FRW_cont">
      <hardwareInterface>VelocityJointInterface</hardwareInterface>
    </joint>
  </transmission>
  <transmission name="MR_wheel_trans" type="SimpleTransmission">
    <type>transmission_interface/SimpleTransmission</type>
    <actuator name="MR_wheel_motor">
      <mechanicalReduction>1</mechanicalReduction>
    </actuator>
    <joint name="MRW_cont">
      <hardwareInterface>VelocityJointInterface</hardwareInterface>
    </joint>
  </transmission>
  <transmission name="RR_wheel_trans" type="SimpleTransmission">
    <type>transmission_interface/SimpleTransmission</type>
    <actuator name="RR_wheel_motor">
      <mechanicalReduction>1</mechanicalReduction>
    </actuator>
    <joint name="RRW_cont">
      <hardwareInterface>VelocityJointInterface</hardwareInterface>
    </joint>
  </transmission>
  <link name="base_laser">
    <inertial>
      <mass value="1.1"/>
      <origin xyz="0 0 0"/>
      <inertia ixx="0.00307156543804" ixy="0.0" ixz="0.0" iyy="0.00312849041527" iyz="0.0" izz="0.00196432421427"/>
    </inertial>
    <visual>
      <origin rpy="0 0 0" xyz="0 0 0"/>
      <geometry>
        <!-- Origin of this mesh is the focal point of the LIDAR. -->
        <mesh filename="package://lms1xx/meshes/sick-lms1xx.dae"/>
      </geometry>
    </visual>
    <collision>
      <origin rpy="0 0 0" xyz="0 0 -0.05"/>
      <geometry>
        <box size="0.105 0.1 0.1"/>
      </geometry>
    </collision>
  </link>
  <gazebo reference="base_laser">
    <turnGravityOff>true</turnGravityOff>
    <sensor name="base_laser" type="ray">
      <pose>0 0 0 0 0 0</pose>
      <visualize>false</visualize>
      <update_rate>50</update_rate>
      <ray>
        <scan>
          <horizontal>
            <samples>720</samples>
            <resolution>1</resolution>
            <min_angle>-2.35619</min_angle>
            <max_angle>2.35619</max_angle>
          </horizontal>
        </scan>
        <range>
          <min>0.10</min>
          <max>30.0</max>
          <resolution>0.01</resolution>
        </range>
        <noise>
          <type>gaussian</type>
          <mean>0.0</mean>
          <stddev>0.001</stddev>
        </noise>
      </ray>
      <plugin filename="libgazebo_ros_laser.so" name="gazebo_ros_laser">
        <topicName>scan</topicName>
        <frameName>base_laser</frameName>
      </plugin>
    </sensor>
  </gazebo>
  <link name="base_laser_mount">
    <visual>
      <origin rpy="0 0 -1.570795" xyz="0 0 0"/>
      <geometry>
        <!-- Origin of this mesh is the base of the bracket. -->
        <mesh filename="package://argo_description/meshes/accessories/lms1xx_mount.dae"/>
      </geometry>
    </visual>
    <collision>
      <origin rpy="0 0 0" xyz="0 0 .0585"/>
      <geometry>
        <box size=".1 .108 .117"/>
      </geometry>
    </collision>
  </link>
  <joint name="base_laser_joint" type="fixed">
    <!-- This offset is from the base of the bracket to the LIDAR's focal point. -->
    <origin rpy="3.14159 0 0" xyz="0.0352 0 0.0566"/>
    <parent link="base_laser_mount"/>
    <child link="base_laser"/>
  </joint>
  <joint name="laser_mount_joint" type="fixed">
    <origin rpy="0.0 0.0 0.0" xyz="0.2206 0.0 0.135"/>
    <parent link="base_link"/>
    <child link="base_laser_mount"/>
  </joint>
  <!--  <xacro:if value="$(arg kinect_enabled)">

      <xacro:sensor_arch prefix="" parent="base_link">
        <origin xyz="-0.35 0 0.51" rpy="0 0 -3.14"/>
      </xacro:sensor_arch>
      <joint name="kinect_frame_joint" type="fixed">
        <origin xyz="$(optenv ARGO_KINECT_XYZ 0 0 0)" rpy="$(optenv ARGO_KINECT_RPY 0 0.18 3.14)" />
        <parent link="base_link"/>
        <child link="camera_link"/>
      </joint>

      <xacro:kinect_camera prefix="camera"/>
    </xacro:if>-->
  <!-- IMU Link is the standard mounting position for the UM6 IMU.-->
  <!-- Can be modified with environment variables in /etc/ros/setup.bash -->
  <link name="imu_link"/>
  <joint name="imu_joint" type="fixed">
    <origin rpy="0 -1.5708 3.1416" xyz="-0.0287146112802265 2.27427526650059E-06 -0.0381581636610044"/>
    <parent link="base_link"/>
    <child link="imu_link"/>
  </joint>
  <gazebo reference="imu_link">
    </gazebo>
</robot>

